<?xml version="1.0" ?>
<robot name="Legs">

  <transmission name="l_b_h_trans" type="pr2_mechanism_model/SimpleTransmission">
    <actuator name="l_b_h_motor"/>
    <joint name="l_hip_abduct"/>
    <mechanicalReduction>1</mechanicalReduction>
  </transmission>
  <transmission name="l_h_tl_trans" type="pr2_mechanism_model/SimpleTransmission">
    <actuator name="l_h_tl_motor"/>
    <joint name="l_hip_flex"/>
    <mechanicalReduction>1</mechanicalReduction>
  </transmission>
  <transmission name="l_tl_bl_trans" type="pr2_mechanism_model/SimpleTransmission">
    <actuator name="l_tl_bl_motor"/>
    <joint name="l_knee"/>
    <mechanicalReduction>1</mechanicalReduction>
  </transmission>
  <transmission name="l_bl_a_trans" type="pr2_mechanism_model/SimpleTransmission">
    <actuator name="l_bl_a_hpz_motor"/>
    <joint name="l_ankle_flex"/>
    <mechanicalReduction>1</mechanicalReduction>
  </transmission>
  <transmission name="l_a_f_trans" type="pr2_mechanism_model/SimpleTransmission">
    <actuator name="l_a_f_motor"/>
    <joint name="l_ankle_roll"/>
    <mechanicalReduction>1</mechanicalReduction>
  </transmission>
  <transmission name="l_f_t_trans" type="pr2_mechanism_model/SimpleTransmission">
    <actuator name="l_f_t_motor"/>
    <joint name="l_toe_flex"/>
    <mechanicalReduction>1</mechanicalReduction>
  </transmission>
  <transmission name="r_b_h_trans" type="pr2_mechanism_model/SimpleTransmission">
    <actuator name="r_b_h_motor"/>
    <joint name="r_hip_abduct"/>
    <mechanicalReduction>1</mechanicalReduction>
  </transmission>
  <transmission name="r_h_tl_trans" type="pr2_mechanism_model/SimpleTransmission">
    <actuator name="r_h_tl_motor"/>
    <joint name="r_hip_flex"/>
    <mechanicalReduction>1</mechanicalReduction>
  </transmission>
  <transmission name="r_tl_bl_trans" type="pr2_mechanism_model/SimpleTransmission">
    <actuator name="r_tl_bl_motor"/>
    <joint name="r_knee"/>
    <mechanicalReduction>1</mechanicalReduction>
  </transmission>
  <transmission name="r_bl_a_trans" type="pr2_mechanism_model/SimpleTransmission">
    <actuator name="r_bl_a_hpz_motor"/>
    <joint name="r_ankle_flex"/>
    <mechanicalReduction>1</mechanicalReduction>
  </transmission>
  <transmission name="r_a_f_trans" type="pr2_mechanism_model/SimpleTransmission">
    <actuator name="r_a_f_motor"/>
    <joint name="r_ankle_roll"/>
    <mechanicalReduction>1</mechanicalReduction>
  </transmission>
  <transmission name="r_f_t_trans" type="pr2_mechanism_model/SimpleTransmission">
    <actuator name="r_f_t_motor"/>
    <joint name="r_toe_flex"/>
    <mechanicalReduction>1</mechanicalReduction>
  </transmission>




  <joint name="l_hip_abduct" type="revolute">
    <parent link="pelvis"/>
    <child link="Biped__Left_Hip"/>
    <origin rpy="1.56567  0      -1.57079" xyz="0.00302  0.05556  0.51514"/>
    <axis xyz="0      -0.00511  0.99998"/>
    <limit effort="100.0" lower="-0.486936705914" upper="0.628150227902" velocity="0.0"/>
  </joint>
  <joint name="l_hip_flex" type="revolute">
    <parent link="Biped__Left_Hip"/>
    <child link="Biped__Top_Left_Leg"/>
    <origin rpy="0  0  0" xyz="-8.05900000e-02  -1.00000000e-05   3.02000000e-03"/>
    <axis xyz="-1  0  0"/>
    <limit effort="100.0" lower="-2.03583339041" upper="2.16044300072" velocity="0.0"/>
  </joint>
  <joint name="l_knee" type="revolute">
    <parent link="Biped__Top_Left_Leg"/>
    <child link="Biped__Bottom_Left_Leg"/>
    <origin rpy="0  0  0" xyz="0.00373 -0.20954 -0.00107"/>
    <axis xyz="-1  0  0"/>
    <limit effort="100.0" lower="-2.61562604133" upper="2.60767984583" velocity="0.0"/>
  </joint>
  <joint name="l_ankle_flex" type="revolute">
    <parent link="Biped__Bottom_Left_Leg"/>
    <child link="Biped__Left_Ankle"/>
    <origin rpy="0  0  0" xyz="-1.50000000e-04  -2.21290000e-01  -1.13000000e-03"/>
    <axis xyz="-1  0  0"/>
    <limit effort="100.0" lower="-1.36043531266" upper="0.135930877095" velocity="0.0"/>
  </joint>
  <joint name="l_ankle_roll" type="revolute">
    <parent link="Biped__Left_Ankle"/>
    <child link="l_foot"/>
    <origin rpy="0  0  0" xyz="-0.00077 -0.0179  -0.06914"/>
    <axis xyz="0      -0.00511  0.99998"/>
    <limit effort="100.0" lower="-1.32128191897" upper="1.32128191897" velocity="0.0"/>
  </joint>
  <joint name="l_toe_flex" type="revolute">
    <parent link="l_foot"/>
    <child link="l_toe"/>
    <origin rpy="0  0  0" xyz="0.00232 -0.03426 -0.06708"/>
    <axis xyz="-1  0  0"/>
    <limit effort="100.0" lower="-0.421908321567" upper="1.92797301525" velocity="0.0"/>
  </joint>
  <joint name="r_hip_abduct" type="revolute">
    <parent link="pelvis"/>
    <child link="Biped__Right_Hip"/>
    <origin rpy="1.56567  0      -1.57079" xyz="-0.00313 -0.05556  0.51514"/>
    <axis xyz="0       0.00511 -0.99998"/>
    <limit effort="100.0" lower="-0.450917249297" upper="0.628150227902" velocity="0.0"/>
  </joint>
  <joint name="r_hip_flex" type="revolute">
    <parent link="Biped__Right_Hip"/>
    <child link="Biped__Top_Right_Leg"/>
    <origin rpy="0  0  0" xyz="7.52400000e-02   1.00000000e-05  -3.13000000e-03"/>
    <axis xyz="-1  0  0"/>
    <limit effort="100.0" lower="-2.03583339041" upper="2.16044300072" velocity="0.0"/>
  </joint>
  <joint name="r_knee" type="revolute">
    <parent link="Biped__Top_Right_Leg"/>
    <child link="Biped__Bottom_Right_Leg"/>
    <origin rpy="0  0  0" xyz="0.00328 -0.20954 -0.00107"/>
    <axis xyz="-1  0  0"/>
    <limit effort="100.0" lower="-2.60767984583" upper="2.60767984583" velocity="0.0"/>
  </joint>
  <joint name="r_ankle_flex" type="revolute">
    <parent link="Biped__Bottom_Right_Leg"/>
    <child link="Biped__Right_Ankle"/>
    <origin rpy="0  0  0" xyz="4.00000000e-05  -2.21290000e-01  -1.13000000e-03"/>
    <axis xyz="-1  0  0"/>
    <limit effort="100.0" lower="-1.34264425814" upper="0.135930877095" velocity="0.0"/>
  </joint>
  <joint name="r_ankle_roll" type="revolute">
    <parent link="Biped__Right_Ankle"/>
    <child link="r_foot"/>
    <origin rpy="0  0  0" xyz="-0.00079 -0.01789 -0.07124"/>
    <axis xyz="0       0.00511 -0.99998"/>
    <limit effort="100.0" lower="-1.32128191897" upper="1.32128191897" velocity="0.0"/>
  </joint>
  <joint name="r_toe_flex" type="revolute">
    <parent link="r_foot"/>
    <child link="r_toe"/>
    <origin rpy="0  0  0" xyz="0.00258 -0.03427 -0.06497"/>
    <axis xyz="-1  0  0"/>
    <limit effort="100.0" lower="-0.421908321567" upper="1.92797301525" velocity="0.0"/>
  </joint>
  <link name="pelvis">
    <inertial>
      <mass value="3.53324885586669"/>
      <origin rpy="1.56567  0      -1.57079" xyz="-7.68000000e-03   1.70000000e-04   6.24330000e-01"/>
      <inertia ixx="0.0271179077728007" ixy="1.18852566353138E-05" ixz="2.95478792996208E-05" iyy="0.0323353494450389" iyz="0.00289482168449842" izz="0.0422145237899791"/>
    </inertial>
    <collision name="Biped__Body_collision">
      <origin rpy="1.56567  0      -1.57079" xyz="0.07092  0.0594   0.21269"/>
      <geometry>
        <mesh filename="meshes/Body_col.STL" scale="1 1 1"/>
      </geometry>
    </collision>
    <visual name="Biped__Body_visual">
      <origin rpy="1.56567  0      -1.57079" xyz="0.07092  0.0594   0.21269"/>
      <geometry>
        <mesh filename="meshes/Body.STL" scale="1 1 1"/>
      </geometry>
    </visual>
  </link>
  <link name="Biped__Left_Hip">
    <inertial>
      <mass value="0.437298303222345"/>
      <origin rpy="0  0  0" xyz="-0.03492  0.03099  0.00015"/>
      <inertia ixx="0.000344658356090036" ixy="1.4438940947967E-05" ixz="5.03774354824921E-05" iyy="0.000819710121372963" iyz="1.99893504999227E-05" izz="0.00066955963284712"/>
    </inertial>
    <collision name="Biped__Left_Hip_collision">
      <origin rpy="0  0  0" xyz="-0.00384 -0.3021  -0.06945"/>
      <geometry>
        <mesh filename="meshes/Left_Hip_col.STL" scale="1 1 1"/>
      </geometry>
    </collision>
    <visual name="Biped__Left_Hip_visual">
      <origin rpy="0  0  0" xyz="-0.00384 -0.3021  -0.06945"/>
      <geometry>
        <mesh filename="meshes/Left_Hip.STL" scale="1 1 1"/>
      </geometry>
    </visual>
  </link>
  <link name="Biped__Top_Left_Leg">
    <inertial>
      <mass value="0.498661421818378"/>
      <origin rpy="0  0  0" xyz="0      -0.09292 -0.00071"/>
      <inertia ixx="0.00222023286489819" ixy="2.76170328092637E-05" ixz="4.42071982951624E-07" iyy="0.000133616406118555" iyz="1.5209311638611E-05" izz="0.00230781854965746"/>
    </inertial>
    <collision name="Biped__Top_Left_Leg_collision">
      <origin rpy="0  0  0" xyz="0.07675 -0.30208 -0.07247"/>
      <geometry>
        <mesh filename="meshes/Top_Left_Leg_col.STL" scale="1 1 1"/>
      </geometry>
    </collision>
    <visual name="Biped__Top_Left_Leg_visual">
      <origin rpy="0  0  0" xyz="0.07675 -0.30208 -0.07247"/>
      <geometry>
        <mesh filename="meshes/Top_Left_Leg.STL" scale="1 1 1"/>
      </geometry>
      <material name="red">
        <color rgba ="0.675 0.169 0.216 1.0"/>
      </material>
    </visual>
  </link>
  <link name="Biped__Bottom_Left_Leg">
    <inertial>
      <mass value="0.512558545145301"/>
      <origin rpy="0  0  0" xyz="0      -0.11018  0.00843"/>
      <inertia ixx="0.00213377963819277" ixy="3.74835359824284E-05" ixz="4.14809936352257E-06" iyy="0.000231679313040171" iyz="0.000107877166470471" izz="0.0021213704718963"/>
    </inertial>
    <collision name="Biped__Bottom_Left_Leg_collision">
      <origin rpy="0  0  0" xyz="0.07301 -0.09254 -0.0714"/>
      <geometry>
        <mesh filename="meshes/Bottom_Left_Leg_col.STL" scale="1 1 1"/>
      </geometry>
    </collision>
    <visual name="Biped__Bottom_Left_Leg_visual">
      <origin rpy="0  0  0" xyz="0.07301 -0.09254 -0.0714"/>
      <geometry>
        <mesh filename="meshes/Bottom_Left_Leg.STL" scale="1 1 1"/>
      </geometry>
      <material name="red"/>
    </visual>
  </link>
  <link name="Biped__Left_Ankle">
    <inertial>
      <mass value="0.117206413777382"/>
      <origin rpy="0  0  0" xyz="0       0.00525  0.02552"/>
      <inertia ixx="0.000111896827570048" ixy="5.94543100842475E-07" ixz="2.57140126177776E-06" iyy="0.000105965848764851" iyz="2.65868228080628E-05" izz="4.20803404080659E-05"/>
    </inertial>
    <collision name="Biped__Left_Ankle_collision">
      <origin rpy="0  0  0" xyz="0.07317  0.12875 -0.07027"/>
      <geometry>
        <mesh filename="meshes/Left_Ankle_col.STL" scale="1 1 1"/>
      </geometry>
    </collision>
    <visual name="Biped__Left_Ankle_visual">
      <origin rpy="0  0  0" xyz="0.07317  0.12875 -0.07027"/>
      <geometry>
        <mesh filename="meshes/Left_Ankle.STL" scale="1 1 1"/>
      </geometry>
      <material name="red"/>
    </visual>
  </link>
  <link name="l_foot">
    <inertial>
      <mass value="0.350801552548944"/>
      <origin rpy="0  0  0" xyz="-0.00146 -0.02757 -0.00014"/>
      <inertia ixx="0.000904665834453429" ixy="7.01175958971625E-06" ixz="4.60520410965569E-06" iyy="0.000926980236054857" iyz="5.01437405892954E-05" izz="0.00014911487451342"/>
    </inertial>
    <collision name="Biped__Left_Foot_collision">
      <origin rpy="0  0  0" xyz="0.07394  0.14666 -0.00112"/>
      <geometry>
        <mesh filename="meshes/Left_Foot_col.STL" scale="1 1 1"/>
      </geometry>
    </collision>
    <visual name="Biped__Left_Foot_visual">
      <origin rpy="0  0  0" xyz="0.07394  0.14666 -0.00112"/>
      <geometry>
        <mesh filename="meshes/Left_Foot.STL" scale="1 1 1"/>
      </geometry>
    </visual>

    <collision group="heel">
      <origin rpy="0 0 0" xyz="0.0139 -0.048 0.1002"/>
      <geometry>
        <sphere radius="0.0"/>
      </geometry>
    </collision>
    <visual group="heel">
      <origin rpy="0 0 0" xyz="0.0139 -0.048 0.1002"/>
      <geometry>
        <sphere radius="0.01"/>
      </geometry>
    </visual>
    <collision group="heel">
      <origin rpy="0 0 0" xyz="-0.0139 -0.048 0.1002"/>
      <geometry>
        <sphere radius="0.0"/>
      </geometry>
    </collision>
    <visual group="heel">
      <origin rpy="0 0 0" xyz="-0.0139 -0.048 0.1002"/>
      <geometry>
        <sphere radius="0.01"/>
      </geometry>
    </visual>

    <collision group="midfoot">
      <origin rpy="0 0 0" xyz="0.0203 -0.0472 -0.0413"/>
      <geometry>
        <sphere radius="0.0"/>
      </geometry>
    </collision>
    <visual group="midfoot">
      <origin rpy="0 0 0" xyz="0.0203 -0.0472 -0.0413"/>
      <geometry>
        <sphere radius="0.01"/>
      </geometry>
    </visual>
    <collision group="midfoot">
      <origin rpy="0 0 0" xyz="-0.0203 -0.0472 -0.0413"/>
      <geometry>
        <sphere radius="0.0"/>
      </geometry>
    </collision>
    <visual group="midfoot">
      <origin rpy="0 0 0" xyz="-0.0203 -0.0472 -0.0413"/>
      <geometry>
        <sphere radius="0.01"/>
      </geometry>
    </visual>

  </link>
  <link name="l_toe">
    <inertial>
      <mass value="0.137471301666086"/>
      <origin rpy="0  0  0" xyz="0       0.00024 -0.03181"/>
      <inertia ixx="5.08521148560519E-05" ixy="3.52897714651812E-06" ixz="4.05786167235431E-06" iyy="6.19912432858944E-05" iyz="1.63142203902691E-06" izz="2.56251883813568E-05"/>
    </inertial>
    <collision name="Biped__Left_Toe_collision">
      <origin rpy="0  0  0" xyz="0.07162  0.18092  0.06595"/>
      <geometry>
        <mesh filename="meshes/Left_Toe_col.STL" scale="1 1 1"/>
      </geometry>
    </collision>
    <visual name="Biped__Left_Toe_visual">
      <origin rpy="0  0  0" xyz="0.07162  0.18092  0.06595"/>
      <geometry>
        <mesh filename="meshes/Left_Toe.STL" scale="1 1 1"/>
      </geometry>
    </visual>

    <collision group="toe">
      <origin rpy="0 0 0" xyz="0.0137 -0.0127 -0.0548"/>
      <geometry>
        <sphere radius="0.0"/>
      </geometry>
    </collision>
    <visual group="toe">
      <origin rpy="0 0 0" xyz="0.0137 -0.0127 -0.0548"/>
      <geometry>
        <sphere radius="0.01"/>
      </geometry>
    </visual>
    <collision group="toe">
      <origin rpy="0 0 0" xyz="-0.0141 -0.0127 -0.0548"/>
      <geometry>
        <sphere radius="0.0"/>
      </geometry>
    </collision>
    <visual group="toe">
      <origin rpy="0 0 0" xyz="-0.0141 -0.0127 -0.0548"/>
      <geometry>
        <sphere radius="0.01"/>
      </geometry>
    </visual>

  </link>
  <link name="Biped__Right_Hip">
    <inertial>
      <mass value="0.429542604129865"/>
      <origin rpy="0  0  0" xyz="0.03461  0.03088  0.00015"/>
      <inertia ixx="0.000335620222780637" ixy="1.71766252899159E-05" ixz="6.82036560203188E-05" iyy="0.000796625170345829" iyz="1.87749814800264E-05" izz="0.000651844767117383"/>
    </inertial>
    <collision name="Biped__Right_Hip_collision">
      <origin rpy="0  0  0" xyz="-0.11497 -0.30207 -0.0756"/>
      <geometry>
        <mesh filename="meshes/Right_Hip_col.STL" scale="1 1 1"/>
      </geometry>
    </collision>
    <visual name="Biped__Right_Hip_visual">
      <origin rpy="0  0  0" xyz="-0.11497 -0.30207 -0.0756"/>
      <geometry>
        <mesh filename="meshes/Right_Hip.STL" scale="1 1 1"/>
      </geometry>
    </visual>
  </link>
  <link name="Biped__Top_Right_Leg">
    <inertial>
      <mass value="0.473894617598188"/>
      <origin rpy="0  0  0" xyz="0      -0.09427 -0.00073"/>
      <inertia ixx="0.00219613513040201" ixy="2.41554166439975E-05" ixz="4.92477643768768E-07" iyy="0.000130736562803138" iyz="1.49414818095768E-05" izz="0.00228460638702232"/>
    </inertial>
    <collision name="Biped__Top_Right_Leg_collision">
      <origin rpy="0  0  0" xyz="-0.19021 -0.30208 -0.07247"/>
      <geometry>
        <mesh filename="meshes/Top_Right_Leg_col.STL" scale="1 1 1"/>
      </geometry>
    </collision>
    <visual name="Biped__Top_Right_Leg_visual">
      <origin rpy="0  0  0" xyz="-0.19021 -0.30208 -0.07247"/>
      <geometry>
        <mesh filename="meshes/Top_Right_Leg.STL" scale="1 1 1"/>
      </geometry>
      <material name="red"/>
    </visual>
  </link>
  <link name="Biped__Bottom_Right_Leg">
    <inertial>
      <mass value="0.496399914621672"/>
      <origin rpy="0  0  0" xyz="0      -0.11414  0.00893"/>
      <inertia ixx="0.00193251368574828" ixy="2.87905126861506E-05" ixz="3.64310219704147E-06" iyy="0.000228879661927419" iyz="9.27392912409724E-05" izz="0.00191229395918849"/>
    </inertial>
    <collision name="Biped__Bottom_Right_Leg_collision">
      <origin rpy="0  0  0" xyz="-0.1935  -0.09254 -0.0714"/>
      <geometry>
        <mesh filename="meshes/Bottom_Right_Leg_col.STL" scale="1 1 1"/>
      </geometry>
    </collision>
    <visual name="Biped__Bottom_Right_Leg_visual">
      <origin rpy="0  0  0" xyz="-0.1935  -0.09254 -0.0714"/>
      <geometry>
        <mesh filename="meshes/Bottom_Right_Leg.STL" scale="1 1 1"/>
      </geometry>
      <material name="red"/>
    </visual>
  </link>
  <link name="Biped__Right_Ankle">
    <inertial>
      <mass value="0.113529232705104"/>
      <origin rpy="0  0  0" xyz="0       0.00601  0.02692"/>
      <inertia ixx="0.000102683690789615" ixy="5.24094963661094E-07" ixz="2.43532379680455E-06" iyy="9.8810717962194E-05" iyz="2.27559446851328E-05" izz="3.98903277983113E-05"/>
    </inertial>
    <collision name="Biped__Right_Ankle_collision">
      <origin rpy="0  0  0" xyz="-0.19355  0.12875 -0.07027"/>
      <geometry>
        <mesh filename="meshes/Right_Ankle_col.STL" scale="1 1 1"/>
      </geometry>
    </collision>
    <visual name="Biped__Right_Ankle_visual">
      <origin rpy="0  0  0" xyz="-0.19355  0.12875 -0.07027"/>
      <geometry>
        <mesh filename="meshes/Right_Ankle.STL" scale="1 1 1"/>
      </geometry>
      <material name="red"/>
    </visual>
  </link>
  <link name="r_foot">
    <inertial>
      <mass value="0.335422598099665"/>
      <origin rpy="0  0  0" xyz="-0.00156 -0.02863 -0.00014"/>
      <inertia ixx="0.000825311286057891" ixy="7.70619999918036E-06" ixz="7.38179683506509E-06" iyy="0.000855538414270564" iyz="7.08159606800129E-05" izz="0.000138582194390659"/>
    </inertial>
    <collision name="Biped__Right_Foot_collision">
      <origin rpy="0  0  0" xyz="-0.19275  0.14664  0.00097"/>
      <geometry>
        <mesh filename="meshes/Right_Foot_col.STL" scale="1 1 1"/>
      </geometry>
    </collision>
    <visual name="Biped__Right_Foot_visual">
      <origin rpy="0  0  0" xyz="-0.19275  0.14664  0.00097"/>
      <geometry>
        <mesh filename="meshes/Right_Foot.STL" scale="1 1 1"/>
      </geometry>
    </visual>

    <collision group="heel">
      <origin rpy="0 0 0" xyz="0.0139 -0.048 0.1015"/>
      <geometry>
        <sphere radius="0.0"/>
      </geometry>
    </collision>
    <visual group="heel">
      <origin rpy="0 0 0" xyz="0.0139 -0.048 0.1015"/>
      <geometry>
        <sphere radius="0.01"/>
      </geometry>
    </visual>
    <collision group="heel">
      <origin rpy="0 0 0" xyz="-0.0139 -0.048 0.1015"/>
      <geometry>
        <sphere radius="0.0"/>
      </geometry>
    </collision>
    <visual group="heel">
      <origin rpy="0 0 0" xyz="-0.0139 -0.048 0.1015"/>
      <geometry>
        <sphere radius="0.01"/>
      </geometry>
    </visual>

    <collision group="midfoot">
      <origin rpy="0 0 0" xyz="0.0202 -0.0473 -0.0395"/>
      <geometry>
        <sphere radius="0.0"/>
      </geometry>
    </collision>
    <visual group="midfoot">
      <origin rpy="0 0 0" xyz="0.0202 -0.0473 -0.0395"/>
      <geometry>
        <sphere radius="0.01"/>
      </geometry>
    </visual>
    <collision group="midfoot">
      <origin rpy="0 0 0" xyz="-0.0202 -0.0473 -0.0395"/>
      <geometry>
        <sphere radius="0.0"/>
      </geometry>
    </collision>
    <visual group="midfoot">
      <origin rpy="0 0 0" xyz="-0.0202 -0.0473 -0.0395"/>
      <geometry>
        <sphere radius="0.01"/>
      </geometry>
    </visual>

  </link>
  <link name="r_toe">
    <inertial>
      <mass value="0.139662029501898"/>
      <origin rpy="0  0  0" xyz="0.00000000e+00   9.00000000e-05  -3.13100000e-02"/>
      <inertia ixx="5.31151672530742E-05" ixy="3.50667566710867E-06" ixz="2.92506381385933E-06" iyy="6.48339665757882E-05" iyz="1.46916802312387E-06" izz="2.62562435591355E-05"/>
    </inertial>
    <collision name="Biped__Right_Toe_collision">
      <origin rpy="0  0  0" xyz="-0.19534  0.18092  0.06595"/>
      <geometry>
        <mesh filename="meshes/Right_Toe_col.STL" scale="1 1 1"/>
      </geometry>
    </collision>
    <visual name="Biped__Right_Toe_visual">
      <origin rpy="0  0  0" xyz="-0.19534  0.18092  0.06595"/>
      <geometry>
        <mesh filename="meshes/Right_Toe.STL" scale="1 1 1"/>
      </geometry>
    </visual>
  </link>

    <collision group="toe">
      <origin rpy="0 0 0" xyz="0.0117 -0.0127 -0.0541"/>
      <geometry>
        <sphere radius="0.0"/>
      </geometry>
    </collision>
    <visual group="toe">
      <origin rpy="0 0 0" xyz="0.0117 -0.0127 -0.0541"/>
      <geometry>
        <sphere radius="0.01"/>
      </geometry>
    </visual>
    <collision group="toe">
      <origin rpy="0 0 0" xyz="-0.0153 -0.0127 -0.0541"/>
      <geometry>
        <sphere radius="0.0"/>
      </geometry>
    </collision>
    <visual group="toe">
      <origin rpy="0 0 0" xyz="-0.0153 -0.0127 -0.0541"/>
      <geometry>
        <sphere radius="0.01"/>
      </geometry>
    </visual>

  <frame link="l_foot" name="Left_Foot_Sole" rpy="0 0 0" xyz="0.0426  0.0017 -0.07645"/>
  <frame link="r_foot" name="Right_Foot_Sole" rpy="0 0 0" xyz="0.0426 -0.0017 -0.07645"/>
  <frame link="l_toe" name="Left_Toe_Sole" rpy="0 0 0" xyz="0.1728 0.0017 -0.07645"/>
  <frame link="r_toe" name="Right_Toe_Sole" rpy="0 0 0" xyz="0.1728 -0.0017 -0.07645"/>

</robot>
